Workbook

Sheet Scoring
A1: Pattern | B1: Model | C1: Response Predicted | D1: Response Unpredicted | E1: LM Non-Responsive | F1: Noise in Output | G1: No Noise in Output | H1: Response Predicted | I1: Response Unpredicted | J1: LM Non-Responsive | K1: Noise in Output | L1: No Noise in Output | M1: Count of Prompts
A2: Simple untuned | B2: claude-sonnet-4-6 | C2: =COUNTIF('Simple untuned'!$W:$W,"expected") -> 122 | D2: =COUNTIF('Simple untuned'!$W:$W,"unexpected") -> 19 | E2: =COUNTIF('Simple untuned'!$W:$W,"confused") -> 14 | F2: =COUNTIF('Simple untuned'!$X:$X,"yes") -> 112 | G2: =COUNTIF('Simple untuned'!$X:$X,"no") -> 43 | H2: =COUNTIF('Simple untuned'!$W:$W,"expected")/(COUNTA('Simple untuned'!$V:$V)-1) -> 0.78709677 | I2: =COUNTIF('Simple untuned'!W:W,"unexpected")/(COUNTA('Simple untuned'!$V:$V)-1) -> 0.12258065 | J2: =COUNTIF('Simple untuned'!W:W,"confused")/(COUNTA('Simple untuned'!$V:$V)-1) -> 0.090322581 | K2: =COUNTIF('Simple untuned'!X:X,"yes")/(COUNTA('Simple untuned'!$V:$V)-1) -> 0.72258065 | L2: =COUNTIF('Simple untuned'!X:X,"no")/(COUNTA('Simple untuned'!$V:$V)-1) -> 0.27741935 | M2: =C2+D2+E2 -> 155
A3: Simple untuned | B3: claude-sonnet-4-5-20250929 | C3: =COUNTIF('Simple untuned'!$Q:$Q,"expected") -> 135 | D3: =COUNTIF('Simple untuned'!$Q:$Q,"unexpected") -> 14 | E3: =COUNTIF('Simple untuned'!$Q:$Q,"confused") -> 6 | F3: =COUNTIF('Simple untuned'!$R:$R,"yes") -> 127 | G3: =COUNTIF('Simple untuned'!$R:$R,"no") -> 28 | H3: =COUNTIF('Simple untuned'!$Q:$Q,"expected")/(COUNTA('Simple untuned'!$P:$P)-1) -> 0.87096774 | I3: =COUNTIF('Simple untuned'!Q:Q,"unexpected")/(COUNTA('Simple untuned'!$P:$P)-1) -> 0.090322581 | J3: =COUNTIF('Simple untuned'!Q:Q,"confused")/(COUNTA('Simple untuned'!$P:$P)-1) -> 0.038709677 | K3: =COUNTIF('Simple untuned'!R:R,"yes")/(COUNTA('Simple untuned'!$P:$P)-1) -> 0.81935484 | L3: =COUNTIF('Simple untuned'!R:R,"no")/(COUNTA('Simple untuned'!$P:$P)-1) -> 0.18064516 | M3: =C3+D3+E3 -> 155
A4: Simple untuned | B4: claude-sonnet-4-20250514 | C4: =COUNTIF('Simple untuned'!$K:$K,"expected") -> 134 | D4: =COUNTIF('Simple untuned'!$K:$K,"unexpected") -> 16 | E4: =COUNTIF('Simple untuned'!$K:$K,"confused") -> 5 | F4: =COUNTIF('Simple untuned'!$L:$L,"yes") -> 146 | G4: =COUNTIF('Simple untuned'!$L:$L,"no") -> 9 | H4: =COUNTIF('Simple untuned'!$K:$K,"expected")/(COUNTA('Simple untuned'!$K:$K)-1) -> 0.86451613 | I4: =COUNTIF('Simple untuned'!K:K,"unexpected")/(COUNTA('Simple untuned'!$K:$K)-1) -> 0.10322581 | J4: =COUNTIF('Simple untuned'!K:K,"confused")/(COUNTA('Simple untuned'!$K:$K)-1) -> 0.032258065 | K4: =COUNTIF('Simple untuned'!L:L,"yes")/(COUNTA('Simple untuned'!$K:$K)-1) -> 0.94193548 | L4: =COUNTIF('Simple untuned'!L:L,"no")/(COUNTA('Simple untuned'!$K:$K)-1) -> 0.058064516 | M4: =C4+D4+E4 -> 155
A5: Simple untuned | B5: gpt-5.4 | C5: =COUNTIF('Simple untuned'!$T:$T,"expected") -> 129 | D5: =COUNTIF('Simple untuned'!$T:$T,"unexpected") -> 11 | E5: =COUNTIF('Simple untuned'!$T:$T,"confused") -> 15 | F5: =COUNTIF('Simple untuned'!$U:$U,"yes") -> 11 | G5: =COUNTIF('Simple untuned'!$U:$U,"no") -> 144 | H5: =COUNTIF('Simple untuned'!$T:$T,"expected")/(COUNTA('Simple untuned'!$T:$T)-1) -> 0.83225806 | I5: =COUNTIF('Simple untuned'!T:T,"unexpected")/(COUNTA('Simple untuned'!$T:$T)-1) -> 0.070967742 | J5: =COUNTIF('Simple untuned'!T:T,"confused")/(COUNTA('Simple untuned'!$T:$T)-1) -> 0.096774194 | K5: =COUNTIF('Simple untuned'!U:U,"yes")/(COUNTA('Simple untuned'!$U:$U)-1) -> 0.070967742 | L5: =COUNTIF('Simple untuned'!U:U,"no")/(COUNTA('Simple untuned'!$U:$U)-1) -> 0.92903226 | M5: =C5+D5+E5 -> 155
A6: Simple untuned | B6: gpt-5 | C6: =COUNTIF('Simple untuned'!$N:$N,"expected") -> 128 | D6: =COUNTIF('Simple untuned'!$N:$N,"unexpected") -> 27 | E6: =COUNTIF('Simple untuned'!$N:$N,"confused") -> 0 | F6: =COUNTIF('Simple untuned'!$O:$O,"yes") -> 0 | G6: =COUNTIF('Simple untuned'!$O:$O,"no") -> 155 | H6: =COUNTIF('Simple untuned'!$N:$N,"expected")/(COUNTA('Simple untuned'!$M:$M)-1) -> 0.82580645 | I6: =COUNTIF('Simple untuned'!N:N,"unexpected")/(COUNTA('Simple untuned'!$M:$M)-1) -> 0.17419355 | J6: =COUNTIF('Simple untuned'!N:N,"confused")/(COUNTA('Simple untuned'!$M:$M)-1) -> 0 | K6: =COUNTIF('Simple untuned'!O:O,"yes")/(COUNTA('Simple untuned'!$M:$M)-1) -> 0 | L6: =COUNTIF('Simple untuned'!O:O,"no")/(COUNTA('Simple untuned'!$M:$M)-1) -> 1 | M6: =C6+D6+E6 -> 155
A7: Simple untuned | B7: gpt-4.1 | C7: =COUNTIF('Simple untuned'!$H:$H,"expected") -> 134 | D7: =COUNTIF('Simple untuned'!$H:$H,"unexpected") -> 18 | E7: =COUNTIF('Simple untuned'!$H:$H,"confused") -> 3 | F7: =COUNTIF('Simple untuned'!$I:$I,"yes") -> 87 | G7: =COUNTIF('Simple untuned'!$I:$I,"no") -> 68 | H7: =COUNTIF('Simple untuned'!$H:$H,"expected")/(COUNTA('Simple untuned'!$H:$H)-1) -> 0.86451613 | I7: =COUNTIF('Simple untuned'!H:H,"unexpected")/(COUNTA('Simple untuned'!$H:$H)-1) -> 0.11612903 | J7: =COUNTIF('Simple untuned'!H:H,"confused")/(COUNTA('Simple untuned'!$H:$H)-1) -> 0.019354839 | K7: =COUNTIF('Simple untuned'!I:I,"yes")/(COUNTA('Simple untuned'!$H:$H)-1) -> 0.56129032 | L7: =COUNTIF('Simple untuned'!I:I,"no")/(COUNTA('Simple untuned'!$H:$H)-1) -> 0.43870968 | M7: =C7+D7+E7 -> 155
A9: Complex untuned | B9: claude-sonnet-4-6 | C9: =COUNTIF('Comple untuned'!$W:$W,"expected") -> 102 | D9: =COUNTIF('Comple untuned'!$W:$W,"unexpected") -> 36 | E9: =COUNTIF('Comple untuned'!$W:$W,"confused") -> 7 | F9: =COUNTIF('Comple untuned'!$X:$X,"yes") -> 139 | G9: =COUNTIF('Comple untuned'!$X:$X,"no") -> 6 | H9: =COUNTIF('Comple untuned'!$W:$W,"expected")/(COUNTA('Comple untuned'!$V:$V)-1) -> 0.70344828 | I9: =COUNTIF('Comple untuned'!W:W,"unexpected")/(COUNTA('Comple untuned'!$V:$V)-1) -> 0.24827586 | J9: =COUNTIF('Comple untuned'!W:W,"confused")/(COUNTA('Comple untuned'!$V:$V)-1) -> 0.048275862 | K9: =COUNTIF('Comple untuned'!X:X,"yes")/(COUNTA('Comple untuned'!$V:$V)-1) -> 0.95862069 | L9: =COUNTIF('Comple untuned'!X:X,"no")/(COUNTA('Comple untuned'!$V:$V)-1) -> 0.04137931 | M9: =C9+D9+E9 -> 145
A10: Complex untuned | B10: claude-sonnet-4-5-20250929 | C10: =COUNTIF('Comple untuned'!$Q:$Q,"expected") -> 105 | D10: =COUNTIF('Comple untuned'!$Q:$Q,"unexpected") -> 36 | E10: =COUNTIF('Comple untuned'!$Q:$Q,"confused") -> 4 | F10: =COUNTIF('Comple untuned'!$R:$R,"yes") -> 59 | G10: =COUNTIF('Comple untuned'!$R:$R,"no") -> 20 | H10: =COUNTIF('Comple untuned'!$Q:$Q,"expected")/(COUNTA('Comple untuned'!$P:$P)-1) -> 0.72413793 | I10: =COUNTIF('Comple untuned'!Q:Q,"unexpected")/(COUNTA('Comple untuned'!$P:$P)-1) -> 0.24827586 | J10: =COUNTIF('Comple untuned'!Q:Q,"confused")/(COUNTA('Comple untuned'!$P:$P)-1) -> 0.027586207 | K10: =COUNTIF('Comple untuned'!R:R,"yes")/(COUNTA('Comple untuned'!$P:$P)-1) -> 0.40689655 | L10: =COUNTIF('Comple untuned'!R:R,"no")/(COUNTA('Comple untuned'!$P:$P)-1) -> 0.13793103 | M10: =C10+D10+E10 -> 145
A11: Complex untuned | B11: claude-sonnet-4-20250514 | C11: =COUNTIF('Comple untuned'!$K:$K,"expected") -> 99 | D11: =COUNTIF('Comple untuned'!$K:$K,"unexpected") -> 38 | E11: =COUNTIF('Comple untuned'!$K:$K,"confused") -> 8 | F11: =COUNTIF('Comple untuned'!$L:$L,"yes") -> 145 | G11: =COUNTIF('Comple untuned'!$L:$L,"no") -> 0 | H11: =COUNTIF('Comple untuned'!$K:$K,"expected")/(COUNTA('Comple untuned'!$J:$J)-1) -> 0.68275862 | I11: =COUNTIF('Comple untuned'!K:K,"unexpected")/(COUNTA('Comple untuned'!$J:$J)-1) -> 0.26206897 | J11: =COUNTIF('Comple untuned'!K:K,"confused")/(COUNTA('Comple untuned'!$J:$J)-1) -> 0.055172414 | K11: =COUNTIF('Comple untuned'!L:L,"yes")/(COUNTA('Comple untuned'!$J:$J)-1) -> 1 | L11: =COUNTIF('Comple untuned'!L:L,"no")/(COUNTA('Comple untuned'!$J:$J)-1) -> 0 | M11: =C11+D11+E11 -> 145
A12: Complex untuned | B12: gpt-5.4 | C12: =COUNTIF('Comple untuned'!$T:$T,"expected") -> 91 | D12: =COUNTIF('Comple untuned'!$T:$T,"unexpected") -> 20 | E12: =COUNTIF('Comple untuned'!$T:$T,"confused") -> 34 | F12: =COUNTIF('Comple untuned'!$U:$U,"yes") -> 33 | G12: =COUNTIF('Comple untuned'!$U:$U,"no") -> 112 | H12: =COUNTIF('Comple untuned'!$T:$T,"expected")/(COUNTA('Comple untuned'!$S:$S)-1) -> 0.62758621 | I12: =COUNTIF('Comple untuned'!T:T,"unexpected")/(COUNTA('Comple untuned'!$S:$S)-1) -> 0.13793103 | J12: =COUNTIF('Comple untuned'!T:T,"confused")/(COUNTA('Comple untuned'!$S:$S)-1) -> 0.23448276 | K12: =COUNTIF('Comple untuned'!U:U,"yes")/(COUNTA('Comple untuned'!$S:$S)-1) -> 0.22758621 | L12: =COUNTIF('Comple untuned'!U:U,"no")/(COUNTA('Comple untuned'!$S:$S)-1) -> 0.77241379 | M12: =C12+D12+E12 -> 145
A13: Complex untuned | B13: gpt-5 | C13: =COUNTIF('Comple untuned'!$N:$N,"expected") -> 126 | D13: =COUNTIF('Comple untuned'!$N:$N,"unexpected") -> 16 | E13: =COUNTIF('Comple untuned'!$N:$N,"confused") -> 3 | F13: =COUNTIF('Comple untuned'!$O:$O,"yes") -> 1 | G13: =COUNTIF('Comple untuned'!$O:$O,"no") -> 144 | H13: =COUNTIF('Comple untuned'!$N:$N,"expected")/(COUNTA('Comple untuned'!$M:$M)-1) -> 0.86896552 | I13: =COUNTIF('Comple untuned'!N:N,"unexpected")/(COUNTA('Comple untuned'!$M:$M)-1) -> 0.11034483 | J13: =COUNTIF('Comple untuned'!N:N,"confused")/(COUNTA('Comple untuned'!$M:$M)-1) -> 0.020689655 | K13: =COUNTIF('Comple untuned'!O:O,"yes")/(COUNTA('Comple untuned'!$M:$M)-1) -> 0.0068965517 | L13: =COUNTIF('Comple untuned'!O:O,"no")/(COUNTA('Comple untuned'!$M:$M)-1) -> 0.99310345 | M13: =C13+D13+E13 -> 145
A14: Complex untuned | B14: gpt-4.1 | C14: =COUNTIF('Comple untuned'!$H:$H,"expected") -> 106 | D14: =COUNTIF('Comple untuned'!$H:$H,"unexpected") -> 39 | E14: =COUNTIF('Comple untuned'!$H:$H,"confused") -> 0 | F14: =COUNTIF('Comple untuned'!$I:$I,"yes") -> 145 | G14: =COUNTIF('Comple untuned'!$I:$I,"no") -> 0 | H14: =COUNTIF('Comple untuned'!$H:$H,"expected")/(COUNTA('Comple untuned'!$G:$G)-1) -> 0.73103448 | I14: =COUNTIF('Comple untuned'!H:H,"unexpected")/(COUNTA('Comple untuned'!$G:$G)-1) -> 0.26896552 | J14: =COUNTIF('Comple untuned'!H:H,"confused")/(COUNTA('Comple untuned'!$G:$G)-1) -> 0 | K14: =COUNTIF('Comple untuned'!I:I,"yes")/(COUNTA('Comple untuned'!$G:$G)-1) -> 1 | L14: =COUNTIF('Comple untuned'!I:I,"no")/(COUNTA('Comple untuned'!$G:$G)-1) -> 0 | M14: =C14+D14+E14 -> 145
A16: Simple (tuned) | B16: claude-sonnet-4-6 | C16: =COUNTIF(Simple!$W:$W,"expected") -> 125 | D16: =COUNTIF(Simple!$W:$W,"unexpected") -> 30 | E16: =COUNTIF(Simple!$W:$W,"confused") -> 0 | F16: =COUNTIF(Simple!$X:$X,"yes") -> 8 | G16: =COUNTIF(Simple!$X:$X,"no") -> 147 | H16: =COUNTIF(Simple!$W:$W,"expected")/(COUNTA(Simple!$W:$W)-1) -> 0.80645161 | I16: =COUNTIF(Simple!W:W,"unexpected")/(COUNTA(Simple!$W:$W)-1) -> 0.19354839 | J16: =COUNTIF(Simple!W:W,"confused")/(COUNTA(Simple!$W:$W)-1) -> 0 | K16: =COUNTIF(Simple!X:X,"yes")/(COUNTA(Simple!$W:$W)-1) -> 0.051612903 | L16: =COUNTIF(Simple!X:X,"no")/(COUNTA(Simple!$W:$W)-1) -> 0.9483871 | M16: =C16+D16+E16 -> 155
A17: Simple (tuned) | B17: claude-sonnet-4-5-20250929 | C17: =COUNTIF(Simple!$Q:$Q,"expected") -> 109 | D17: =COUNTIF(Simple!$Q:$Q,"unexpected") -> 24 | E17: =COUNTIF(Simple!$Q:$Q,"confused") -> 22 | F17: =COUNTIF(Simple!$R:$R,"yes") -> 0 | G17: =COUNTIF(Simple!$R:$R,"no") -> 155 | H17: =COUNTIF(Simple!$Q:$Q,"expected")/(COUNTA(Simple!$Q:$Q)-1) -> 0.70322581 | I17: =COUNTIF(Simple!Q:Q,"unexpected")/(COUNTA(Simple!$Q:$Q)-1) -> 0.15483871 | J17: =COUNTIF(Simple!Q:Q,"confused")/(COUNTA(Simple!$Q:$Q)-1) -> 0.14193548 | K17: =COUNTIF(Simple!R:R,"yes")/(COUNTA(Simple!$Q:$Q)-1) -> 0 | L17: =COUNTIF(Simple!R:R,"no")/(COUNTA(Simple!$Q:$Q)-1) -> 1 | M17: =C17+D17+E17 -> 155
A18: Simple (tuned) | B18: claude-sonnet-4-20250514 | C18: =COUNTIF(Simple!$K:$K,"expected") -> 108 | D18: =COUNTIF(Simple!$K:$K,"unexpected") -> 36 | E18: =COUNTIF(Simple!$K:$K,"confused") -> 11 | F18: =COUNTIF(Simple!$L:$L,"yes") -> 0 | G18: =COUNTIF(Simple!$L:$L,"no") -> 155 | H18: =COUNTIF(Simple!$K:$K,"expected")/(COUNTA(Simple!$K:$K)-1) -> 0.69677419 | I18: =COUNTIF(Simple!K:K,"unexpected")/(COUNTA(Simple!$K:$K)-1) -> 0.23225806 | J18: =COUNTIF(Simple!K:K,"incorrect")/(COUNTA(Simple!$K:$K)-1) -> 0 | K18: =COUNTIF(Simple!L:L,"yes")/(COUNTA(Simple!$K:$K)-1) -> 0 | L18: =COUNTIF(Simple!L:L,"no")/(COUNTA(Simple!$K:$K)-1) -> 1 | M18: =C18+D18+E18 -> 155
A19: Simple (tuned) | B19: gpt-5.4 | C19: =COUNTIF(Simple!$T:$T,"expected") -> 137 | D19: =COUNTIF(Simple!$T:$T,"unexpected") -> 18 | E19: =COUNTIF(Simple!$T:$T,"confused") -> 0 | F19: =COUNTIF(Simple!$U:$U,"yes") -> 0 | G19: =COUNTIF(Simple!$U:$U,"no") -> 155 | H19: =COUNTIF(Simple!$T:$T,"expected")/(COUNTA(Simple!$T:$T)-1) -> 0.88387097 | I19: =COUNTIF(Simple!T:T,"unexpected")/(COUNTA(Simple!$T:$T)-1) -> 0.11612903 | J19: =COUNTIF(Simple!T:T,"confused")/(COUNTA(Simple!$T:$T)-1) -> 0 | K19: =COUNTIF(Simple!U:U,"yes")/(COUNTA(Simple!$T:$T)-1) -> 0 | L19: =COUNTIF(Simple!U:U,"no")/(COUNTA(Simple!$T:$T)-1) -> 1 | M19: =C19+D19+E19 -> 155
A20: Simple (tuned) | B20: gpt-5 | C20: =COUNTIF(Simple!$N:$N,"expected") -> 132 | D20: =COUNTIF(Simple!$N:$N,"unexpected") -> 23 | E20: =COUNTIF(Simple!$N:$N,"confused") -> 0 | F20: =COUNTIF(Simple!$O:$O,"yes") -> 0 | G20: =COUNTIF(Simple!$O:$O,"no") -> 155 | H20: =COUNTIF(Simple!$N:$N,"expected")/(COUNTA(Simple!$N:$N)-1) -> 0.8516129 | I20: =COUNTIF(Simple!N:N,"unexpected")/(COUNTA(Simple!$N:$N)-1) -> 0.1483871 | J20: =COUNTIF(Simple!N:N,"confused")/(COUNTA(Simple!$N:$N)-1) -> 0 | K20: =COUNTIF(Simple!O:O,"yes")/(COUNTA(Simple!$N:$N)-1) -> 0 | L20: =COUNTIF(Simple!O:O,"no")/(COUNTA(Simple!$N:$N)-1) -> 1 | M20: =C20+D20+E20 -> 155
A21: Simple (tuned) | B21: gpt-4.1 | C21: =COUNTIF(Simple!$H:$H,"expected") -> 137 | D21: =COUNTIF(Simple!$H:$H,"unexpected") -> 18 | E21: =COUNTIF(Simple!$H:$H,"confused") -> 0 | F21: =COUNTIF(Simple!$I:$I,"yes") -> 0 | G21: =COUNTIF(Simple!$I:$I,"no") -> 155 | H21: =COUNTIF(Simple!$H:$H,"expected")/(COUNTA(Simple!$H:$H)-1) -> 0.88387097 | I21: =COUNTIF(Simple!H:H,"unexpected")/(COUNTA(Simple!$H:$H)-1) -> 0.11612903 | J21: =COUNTIF(Simple!H:H,"confused")/(COUNTA(Simple!$H:$H)-1) -> 0 | K21: =COUNTIF(Simple!I:I,"yes")/(COUNTA(Simple!$H:$H)-1) -> 0 | L21: =COUNTIF(Simple!I:I,"no")/(COUNTA(Simple!$H:$H)-1) -> 1 | M21: =C21+D21+E21 -> 155
A23: Complex (tuned) | B23: claude-sonnet-4-6 | C23: =COUNTIF(Complex!$W:$W,"expected") -> 98 | D23: =COUNTIF(Complex!$W:$W,"unexpected") -> 47 | E23: =COUNTIF(Complex!$W:$W,"confused") -> 0 | F23: =COUNTIF(Complex!$X:$X,"yes") -> 0 | G23: =COUNTIF(Complex!$X:$X,"no") -> 145 | H23: =COUNTIF(Complex!$W:$W,"expected")/(COUNTA(Complex!$W:$W)-1) -> 0.67586207 | I23: =COUNTIF(Complex!$W:$W,"unexpected")/(COUNTA(Complex!$W:$W)-1) -> 0.32413793 | J23: =COUNTIF(Complex!$W:$W,"confused")/(COUNTA(Complex!$W:$W)-1) -> 0 | K23: =COUNTIF(Complex!$X:$X,"yes")/(COUNTA(Complex!$X:$X)-1) -> 0 | L23: =COUNTIF(Complex!$X:$X,"no")/(COUNTA(Complex!$X:$X)-1) -> 1 | M23: =C23+D23+E23 -> 145
A24: Complex (tuned) | B24: claude-sonnet-4-5-20250929 | C24: =COUNTIF(Complex!$Q:$Q,"expected") -> 105 | D24: =COUNTIF(Complex!$Q:$Q,"unexpected") -> 40 | E24: =COUNTIF(Complex!$Q:$Q,"confused") -> 0 | F24: =COUNTIF(Complex!$R:$R,"yes") -> 0 | G24: =COUNTIF(Complex!$R:$R,"no") -> 145 | H24: =COUNTIF(Complex!$Q:$Q,"expected")/(COUNTA(Complex!$Q:$Q)-1) -> 0.72413793 | I24: =COUNTIF(Complex!$Q:$Q,"unexpected")/(COUNTA(Complex!$Q:$Q)-1) -> 0.27586207 | J24: =COUNTIF(Complex!$Q:$Q,"confused")/(COUNTA(Complex!$Q:$Q)-1) -> 0 | K24: =COUNTIF(Complex!$R:$R,"yes")/(COUNTA(Complex!$R:$R)-1) -> 0 | L24: =COUNTIF(Complex!$R:$R,"no")/(COUNTA(Complex!$R:$R)-1) -> 1 | M24: =C24+D24+E24 -> 145
A25: Complex (tuned) | B25: claude-sonnet-4-20250514 | C25: =COUNTIF(Complex!$K:$K,"expected") -> 113 | D25: =COUNTIF(Complex!$K:$K,"unexpected") -> 31 | E25: =COUNTIF(Complex!$K:$K,"confused") -> 1 | F25: =COUNTIF(Complex!$L:$L,"yes") -> 38 | G25: =COUNTIF(Complex!$L:$L,"no") -> 107 | H25: =COUNTIF(Complex!$K:$K,"expected")/(COUNTA(Complex!$K:$K)-1) -> 0.77931034 | I25: =COUNTIF(Complex!$K:$K,"unexpected")/(COUNTA(Complex!$K:$K)-1) -> 0.2137931 | J25: =COUNTIF(Complex!$K:$K,"confused")/(COUNTA(Complex!$K:$K)-1) -> 0.0068965517 | K25: =COUNTIF(Complex!$L:$L,"yes")/(COUNTA(Complex!$K:$K)-1) -> 0.26206897 | L25: =COUNTIF(Complex!L:L,"no")/(COUNTA(Complex!$K:$K)-1) -> 0.73793103 | M25: =C25+D25+E25 -> 145
A26: Complex (tuned) | B26: gpt-5.4 | C26: =COUNTIF(Complex!$T:$T,"expected") -> 103 | D26: =COUNTIF(Complex!$T:$T,"unexpected") -> 42 | E26: =COUNTIF(Complex!$T:$T,"confused") -> 0 | F26: =COUNTIF(Complex!$U:$U,"yes") -> 0 | G26: =COUNTIF(Complex!$U:$U,"no") -> 145 | H26: =COUNTIF(Complex!$T:$T,"expected")/(COUNTA(Complex!$T:$T)-1) -> 0.71034483 | I26: =COUNTIF(Complex!T:T,"unexpected")/(COUNTA(Complex!$T:$T)-1) -> 0.28965517 | J26: =COUNTIF(Complex!T:T,"confused")/(COUNTA(Complex!$T:$T)-1) -> 0 | K26: =COUNTIF(Complex!U:U,"yes")/(COUNTA(Complex!$T:$T)-1) -> 0 | L26: =COUNTIF(Complex!U:U,"no")/(COUNTA(Complex!$T:$T)-1) -> 1 | M26: =C26+D26+E26 -> 145
A27: Complex (tuned) | B27: gpt-5 | C27: =COUNTIF(Complex!$N:$N,"expected") -> 124 | D27: =COUNTIF(Complex!$N:$N,"unexpected") -> 21 | E27: =COUNTIF(Complex!$N:$N,"confused") -> 0 | F27: =COUNTIF(Complex!$O:$O,"yes") -> 0 | G27: =COUNTIF(Complex!$O:$O,"no") -> 145 | H27: =COUNTIF(Complex!$N:$N,"expected")/(COUNTA(Complex!$N:$N)-1) -> 0.85517241 | I27: =COUNTIF(Complex!N:N,"unexpected")/(COUNTA(Complex!$N:$N)-1) -> 0.14482759 | J27: =COUNTIF(Complex!N:N,"confused")/(COUNTA(Complex!$N:$N)-1) -> 0 | K27: =COUNTIF(Complex!O:O,"yes")/(COUNTA(Complex!$N:$N)-1) -> 0 | L27: =COUNTIF(Complex!O:O,"no")/(COUNTA(Complex!$N:$N)-1) -> 1 | M27: =C27+D27+E27 -> 145
A28: Complex (tuned) | B28: gpt-4.1 | C28: =COUNTIF(Complex!$H:$H,"expected") -> 110 | D28: =COUNTIF(Complex!$H:$H,"unexpected") -> 35 | E28: =COUNTIF(Complex!$H:$H,"confused") -> 0 | F28: =COUNTIF(Complex!$I:$I,"yes") -> 0 | G28: =COUNTIF(Complex!$I:$I,"no") -> 145 | H28: =COUNTIF(Complex!$H:$H,"expected")/(COUNTA(Complex!$H:$H)-1) -> 0.75862069 | I28: =COUNTIF(Complex!H:H,"unexpected")/(COUNTA(Complex!$H:$H)-1) -> 0.24137931 | J28: =COUNTIF(Complex!H:H,"confused")/(COUNTA(Complex!$H:$H)-1) -> 0 | K28: =COUNTIF(Complex!I:I,"yes")/(COUNTA(Complex!$H:$H)-1) -> 0 | L28: =COUNTIF(Complex!I:I,"no")/(COUNTA(Complex!$H:$H)-1) -> 1 | M28: =C28+D28+E28 -> 145
A30: Complex-Prio-Food | B30: claude-sonnet-4-6 | C30: =COUNTIF('Complex-Prio-Food'!$W:$W,"expected") -> 71 | D30: =COUNTIF('Complex-Prio-Food'!$W:$W,"unexpected") -> 74 | E30: =COUNTIF('Complex-Prio-Food'!$W:$W,"confused") -> 0 | F30: =COUNTIF('Complex-Prio-Food'!$X:$X,"yes") -> 0 | G30: =COUNTIF('Complex-Prio-Food'!$X:$X,"no") -> 145 | H30: =COUNTIF('Complex-Prio-Food'!$W:$W,"expected")/(COUNTA('Complex-Prio-Food'!$W:$W)-1) -> 0.48965517 | I30: =COUNTIF('Complex-Prio-Food'!W:W,"unexpected")/(COUNTA('Complex-Prio-Food'!$W:$W)-1) -> 0.51034483 | J30: =COUNTIF('Complex-Prio-Food'!W:W,"confused")/(COUNTA('Complex-Prio-Food'!$W:$W)-1) -> 0 | K30: =COUNTIF('Complex-Prio-Food'!X:X,"yes")/(COUNTA('Complex-Prio-Food'!$X:$X)-1) -> 0 | L30: =COUNTIF('Complex-Prio-Food'!X:X,"no")/(COUNTA('Complex-Prio-Food'!$X:$X)-1) -> 1 | M30: =C30+D30+E30 -> 145
A31: Complex-Prio-Food | B31: claude-sonnet-4-5-20250929 | C31: =COUNTIF('Complex-Prio-Food'!$Q:$Q,"expected") -> 78 | D31: =COUNTIF('Complex-Prio-Food'!$Q:$Q,"unexpected") -> 67 | E31: =COUNTIF('Complex-Prio-Food'!$Q:$Q,"confused") -> 0 | F31: =COUNTIF('Complex-Prio-Food'!$R:$R,"yes") -> 0 | G31: =COUNTIF('Complex-Prio-Food'!$R:$R,"no") -> 145 | H31: =COUNTIF('Complex-Prio-Food'!$Q:$Q,"expected")/(COUNTA('Complex-Prio-Food'!$Q:$Q)-1) -> 0.53793103 | I31: =COUNTIF('Complex-Prio-Food'!Q:Q,"unexpected")/(COUNTA('Complex-Prio-Food'!$Q:$Q)-1) -> 0.46206897 | J31: =COUNTIF('Complex-Prio-Food'!Q:Q,"confused")/(COUNTA('Complex-Prio-Food'!$Q:$Q)-1) -> 0 | K31: =COUNTIF('Complex-Prio-Food'!R:R,"yes")/(COUNTA('Complex-Prio-Food'!$R:$R)-1) -> 0 | L31: =COUNTIF('Complex-Prio-Food'!R:R,"no")/(COUNTA('Complex-Prio-Food'!$R:$R)-1) -> 1 | M31: =C31+D31+E31 -> 145
A32: Complex-Prio-Food | B32: claude-sonnet-4-20250514 | C32: =COUNTIF('Complex-Prio-Food'!$K:$K,"expected") -> 73 | D32: =COUNTIF('Complex-Prio-Food'!$K:$K,"unexpected") -> 70 | E32: =COUNTIF('Complex-Prio-Food'!$K:$K,"confused") -> 2 | F32: =COUNTIF('Complex-Prio-Food'!$L:$L,"yes") -> 9 | G32: =COUNTIF('Complex-Prio-Food'!$L:$L,"no") -> 136 | H32: =COUNTIF('Complex-Prio-Food'!$K:$K,"expected")/(COUNTA('Complex-Prio-Food'!$K:$K)-1) -> 0.50344828 | I32: =COUNTIF('Complex-Prio-Food'!K:K,"unexpected")/(COUNTA('Complex-Prio-Food'!$K:$K)-1) -> 0.48275862 | J32: =COUNTIF('Complex-Prio-Food'!K:K,"confused")/(COUNTA('Complex-Prio-Food'!$K:$K)-1) -> 0.013793103 | K32: =COUNTIF('Complex-Prio-Food'!L:L,"yes")/(COUNTA('Complex-Prio-Food'!$L:$L)-1) -> 0.062068966 | L32: =COUNTIF('Complex-Prio-Food'!L:L,"no")/(COUNTA('Complex-Prio-Food'!$L:$L)-1) -> 0.93793103 | M32: =C32+D32+E32 -> 145
A33: Complex-Prio-Food | B33: gpt-5.4 | C33: =COUNTIF('Complex-Prio-Food'!$T:$T,"expected") -> 81 | D33: =COUNTIF('Complex-Prio-Food'!$T:$T,"unexpected") -> 64 | E33: =COUNTIF('Complex-Prio-Food'!$T:$T,"confused") -> 0 | F33: =COUNTIF('Complex-Prio-Food'!$U:$U,"yes") -> 0 | G33: =COUNTIF('Complex-Prio-Food'!$U:$U,"no") -> 145 | H33: =COUNTIF('Complex-Prio-Food'!$T:$T,"expected")/(COUNTA('Complex-Prio-Food'!$T:$T)-1) -> 0.55862069 | I33: =COUNTIF('Complex-Prio-Food'!T:T,"unexpected")/(COUNTA('Complex-Prio-Food'!$Q:$Q)-1) -> 0.44137931 | J33: =COUNTIF('Complex-Prio-Food'!T:T,"confused")/(COUNTA('Complex-Prio-Food'!$Q:$Q)-1) -> 0 | K33: =COUNTIF('Complex-Prio-Food'!U:U,"yes")/(COUNTA('Complex-Prio-Food'!$U:$U)-1) -> 0 | L33: =COUNTIF('Complex-Prio-Food'!U:U,"no")/(COUNTA('Complex-Prio-Food'!$U:$U)-1) -> 1 | M33: =C33+D33+E33 -> 145
A34: Complex-Prio-Food | B34: gpt-5 | C34: =COUNTIF('Complex-Prio-Food'!$N:$N,"expected") -> 124 | D34: =COUNTIF('Complex-Prio-Food'!$N:$N,"unexpected") -> 21 | E34: =COUNTIF('Complex-Prio-Food'!$N:$N,"confused") -> 0 | F34: =COUNTIF('Complex-Prio-Food'!$O:$O,"yes") -> 0 | G34: =COUNTIF('Complex-Prio-Food'!$O:$O,"no") -> 145 | H34: =COUNTIF('Complex-Prio-Food'!$N:$N,"expected")/(COUNTA('Complex-Prio-Food'!$N:$N)-1) -> 0.85517241 | I34: =COUNTIF('Complex-Prio-Food'!N:N,"unexpected")/(COUNTA('Complex-Prio-Food'!$N:$N)-1) -> 0.14482759 | J34: =COUNTIF('Complex-Prio-Food'!N:N,"confused")/(COUNTA('Complex-Prio-Food'!$N:$N)-1) -> 0 | K34: =COUNTIF('Complex-Prio-Food'!O:O,"yes")/(COUNTA('Complex-Prio-Food'!$O:$O)-1) -> 0 | L34: =COUNTIF('Complex-Prio-Food'!O:O,"no")/(COUNTA('Complex-Prio-Food'!$O:$O)-1) -> 1 | M34: =C34+D34+E34 -> 145
A35: Complex-Prio-Food | B35: gpt-4.1 | C35: =COUNTIF('Complex-Prio-Food'!$H:$H,"expected") -> 85 | D35: =COUNTIF('Complex-Prio-Food'!$H:$H,"unexpected") -> 60 | E35: =COUNTIF('Complex-Prio-Food'!$H:$H,"confused") -> 0 | F35: =COUNTIF('Complex-Prio-Food'!$I:$I,"yes") -> 0 | G35: =COUNTIF('Complex-Prio-Food'!$I:$I,"no") -> 145 | H35: =COUNTIF('Complex-Prio-Food'!$H:$H,"expected")/(COUNTA('Complex-Prio-Food'!$H:$H)-1) -> 0.5862069 | I35: =COUNTIF('Complex-Prio-Food'!H:H,"unexpected")/(COUNTA('Complex-Prio-Food'!$H:$H)-1) -> 0.4137931 | J35: =COUNTIF('Complex-Prio-Food'!H:H,"confused")/(COUNTA('Complex-Prio-Food'!$H:$H)-1) -> 0 | K35: =COUNTIF('Complex-Prio-Food'!I:I,"yes")/(COUNTA('Complex-Prio-Food'!$H:$H)-1) -> 0 | L35: =COUNTIF('Complex-Prio-Food'!I:I,"no")/(COUNTA('Complex-Prio-Food'!$H:$H)-1) -> 1 | M35: =C35+D35+E35 -> 145
A36: Complex-Prio-Profession | B36: claude-sonnet-4-6 | C36: =COUNTIF('Complex-Prio-Profession'!$W:$W,"expected") -> 71 | D36: =COUNTIF('Complex-Prio-Profession'!$W:$W,"unexpected") -> 74 | E36: =COUNTIF('Complex-Prio-Profession'!$W:$W,"confused") -> 0 | F36: =COUNTIF('Complex-Prio-Profession'!$X:$X,"yes") -> 0 | G36: =COUNTIF('Complex-Prio-Profession'!$X:$X,"no") -> 145 | H36: =COUNTIF('Complex-Prio-Profession'!$W:$W,"expected")/(COUNTA('Complex-Prio-Profession'!$W:$W)-1) -> 0.48965517 | I36: =COUNTIF('Complex-Prio-Profession'!W:W,"unexpected")/(COUNTA('Complex-Prio-Profession'!$W:$W)-1) -> 0.51034483 | J36: =COUNTIF('Complex-Prio-Profession'!W:W,"confused")/(COUNTA('Complex-Prio-Profession'!$W:$W)-1) -> 0 | K36: =COUNTIF('Complex-Prio-Profession'!X:X,"yes")/(COUNTA('Complex-Prio-Profession'!$X:$X)-1) -> 0 | L36: =COUNTIF('Complex-Prio-Profession'!X:X,"no")/(COUNTA('Complex-Prio-Profession'!$X:$X)-1) -> 1 | M36: =C36+D36+E36 -> 145
A37: Complex-Prio-Profession | B37: claude-sonnet-4-5-20250929 | C37: =COUNTIF('Complex-Prio-Profession'!$Q:$Q,"expected") -> 82 | D37: =COUNTIF('Complex-Prio-Profession'!$Q:$Q,"unexpected") -> 63 | E37: =COUNTIF('Complex-Prio-Profession'!$Q:$Q,"confused") -> 0 | F37: =COUNTIF('Complex-Prio-Profession'!$R:$R,"yes") -> 0 | G37: =COUNTIF('Complex-Prio-Profession'!$R:$R,"no") -> 145 | H37: =COUNTIF('Complex-Prio-Profession'!$Q:$Q,"expected")/(COUNTA('Complex-Prio-Profession'!$Q:$Q)-1) -> 0.56551724 | I37: =COUNTIF('Complex-Prio-Profession'!Q:Q,"unexpected")/(COUNTA('Complex-Prio-Profession'!$Q:$Q)-1) -> 0.43448276 | J37: =COUNTIF('Complex-Prio-Profession'!Q:Q,"confused")/(COUNTA('Complex-Prio-Profession'!$Q:$Q)-1) -> 0 | K37: =COUNTIF('Complex-Prio-Profession'!R:R,"yes")/(COUNTA('Complex-Prio-Profession'!$R:$R)-1) -> 0 | L37: =COUNTIF('Complex-Prio-Profession'!R:R,"no")/(COUNTA('Complex-Prio-Profession'!$R:$R)-1) -> 1 | M37: =C37+D37+E37 -> 145
A38: Complex-Prio-Profession | B38: claude-sonnet-4-20250514 | C38: =COUNTIF('Complex-Prio-Profession'!$K:$K,"expected") -> 88 | D38: =COUNTIF('Complex-Prio-Profession'!$K:$K,"unexpected") -> 57 | E38: =COUNTIF('Complex-Prio-Profession'!$K:$K,"confused") -> 0 | F38: =COUNTIF('Complex-Prio-Profession'!$L:$L,"yes") -> 22 | G38: =COUNTIF('Complex-Prio-Profession'!$L:$L,"no") -> 123 | H38: =COUNTIF('Complex-Prio-Profession'!$K:$K,"expected")/(COUNTA('Complex-Prio-Profession'!$K:$K)-1) -> 0.60689655 | I38: =COUNTIF('Complex-Prio-Profession'!K:K,"unexpected")/(COUNTA('Complex-Prio-Profession'!$K:$K)-1) -> 0.39310345 | J38: =COUNTIF('Complex-Prio-Profession'!K:K,"confused")/(COUNTA('Complex-Prio-Profession'!$K:$K)-1) -> 0 | K38: =COUNTIF('Complex-Prio-Profession'!L:L,"yes")/(COUNTA('Complex-Prio-Profession'!$L:$L)-1) -> 0.15172414 | L38: =COUNTIF('Complex-Prio-Profession'!L:L,"no")/(COUNTA('Complex-Prio-Profession'!$L:$L)-1) -> 0.84827586 | M38: =C38+D38+E38 -> 145
A39: Complex-Prio-Profession | B39: gpt-5.4 | C39: =COUNTIF('Complex-Prio-Profession'!$T:$T,"expected") -> 86 | D39: =COUNTIF('Complex-Prio-Profession'!$T:$T,"unexpected") -> 59 | E39: =COUNTIF('Complex-Prio-Profession'!$T:$T,"confused") -> 0 | F39: =COUNTIF('Complex-Prio-Profession'!$U:$U,"yes") -> 0 | G39: =COUNTIF('Complex-Prio-Profession'!$U:$U,"no") -> 145 | H39: =COUNTIF('Complex-Prio-Profession'!$T:$T,"expected")/(COUNTA('Complex-Prio-Profession'!$T:$T)-1) -> 0.59310345 | I39: =COUNTIF('Complex-Prio-Profession'!T:T,"unexpected")/(COUNTA('Complex-Prio-Profession'!$T:$T)-1) -> 0.40689655 | J39: =COUNTIF('Complex-Prio-Profession'!T:T,"confused")/(COUNTA('Complex-Prio-Profession'!$T:$T)-1) -> 0 | K39: =COUNTIF('Complex-Prio-Profession'!U:U,"yes")/(COUNTA('Complex-Prio-Profession'!$U:$U)-1) -> 0 | L39: =COUNTIF('Complex-Prio-Profession'!U:U,"no")/(COUNTA('Complex-Prio-Profession'!$U:$U)-1) -> 1 | M39: =C39+D39+E39 -> 145
A40: Complex-Prio-Profession | B40: gpt-5 | C40: =COUNTIF('Complex-Prio-Profession'!$N:$N,"expected") -> 126 | D40: =COUNTIF('Complex-Prio-Profession'!$N:$N,"unexpected") -> 19 | E40: =COUNTIF('Complex-Prio-Profession'!$N:$N,"confused") -> 0 | F40: =COUNTIF('Complex-Prio-Profession'!$O:$O,"yes") -> 0 | G40: =COUNTIF('Complex-Prio-Profession'!$O:$O,"no") -> 145 | H40: =COUNTIF('Complex-Prio-Profession'!$N:$N,"expected")/(COUNTA('Complex-Prio-Profession'!$N:$N)-1) -> 0.86896552 | I40: =COUNTIF('Complex-Prio-Profession'!N:N,"unexpected")/(COUNTA('Complex-Prio-Profession'!$H:$H)-1) -> 0.13103448 | J40: =COUNTIF('Complex-Prio-Profession'!N:N,"confused")/(COUNTA('Complex-Prio-Profession'!$H:$H)-1) -> 0 | K40: =COUNTIF('Complex-Prio-Profession'!O:O,"yes")/(COUNTA('Complex-Prio-Profession'!$O:$O)-1) -> 0 | L40: =COUNTIF('Complex-Prio-Profession'!O:O,"no")/(COUNTA('Complex-Prio-Profession'!$O:$O)-1) -> 1 | M40: =C40+D40+E40 -> 145
A41: Complex-Prio-Profession | B41: gpt-4.1 | C41: =COUNTIF('Complex-Prio-Profession'!$H:$H,"expected") -> 89 | D41: =COUNTIF('Complex-Prio-Profession'!$H:$H,"unexpected") -> 56 | E41: =COUNTIF('Complex-Prio-Profession'!$H:$H,"confused") -> 0 | F41: =COUNTIF('Complex-Prio-Profession'!$I:$I,"yes") -> 0 | G41: =COUNTIF('Complex-Prio-Profession'!$I:$I,"no") -> 145 | H41: =COUNTIF('Complex-Prio-Profession'!$H:$H,"expected")/(COUNTA('Complex-Prio-Profession'!$H:$H)-1) -> 0.6137931 | I41: =COUNTIF('Complex-Prio-Profession'!H:H,"unexpected")/(COUNTA('Complex-Prio-Profession'!$H:$H)-1) -> 0.3862069 | J41: =COUNTIF('Complex-Prio-Profession'!H:H,"confused")/(COUNTA('Complex-Prio-Profession'!$H:$H)-1) -> 0 | K41: =COUNTIF('Complex-Prio-Profession'!I:I,"yes")/(COUNTA('Complex-Prio-Profession'!$H:$H)-1) -> 0 | L41: =COUNTIF('Complex-Prio-Profession'!I:I,"no")/(COUNTA('Complex-Prio-Profession'!$H:$H)-1) -> 1 | M41: =C41+D41+E41 -> 145
A42: Complex-Prio-Sentiment | B42: claude-sonnet-4-6 | C42: =COUNTIF('Complex-Prio-Sentiment'!$W:$W,"expected") -> 72 | D42: =COUNTIF('Complex-Prio-Sentiment'!$W:$W,"unexpected") -> 73 | E42: =COUNTIF('Complex-Prio-Sentiment'!$W:$W,"confused") -> 0 | F42: =COUNTIF('Complex-Prio-Sentiment'!$X:$X,"yes") -> 0 | G42: =COUNTIF('Complex-Prio-Sentiment'!$X:$X,"no") -> 145 | H42: =COUNTIF('Complex-Prio-Sentiment'!$W:$W,"expected")/(COUNTA('Complex-Prio-Sentiment'!$W:$W)-1) -> 0.49655172 | I42: =COUNTIF('Complex-Prio-Sentiment'!W:W,"unexpected")/(COUNTA('Complex-Prio-Sentiment'!$W:$W)-1) -> 0.50344828 | J42: =COUNTIF('Complex-Prio-Sentiment'!W:W,"confused")/(COUNTA('Complex-Prio-Sentiment'!$W:$W)-1) -> 0 | K42: =COUNTIF('Complex-Prio-Sentiment'!X:X,"yes")/(COUNTA('Complex-Prio-Sentiment'!$X:$X)-1) -> 0 | L42: =COUNTIF('Complex-Prio-Sentiment'!X:X,"no")/(COUNTA('Complex-Prio-Sentiment'!$X:$X)-1) -> 1 | M42: =C42+D42+E42 -> 145
A43: Complex-Prio-Sentiment | B43: claude-sonnet-4-5-20250929 | C43: =COUNTIF('Complex-Prio-Sentiment'!$Q:$Q,"expected") -> 83 | D43: =COUNTIF('Complex-Prio-Sentiment'!$Q:$Q,"unexpected") -> 62 | E43: =COUNTIF('Complex-Prio-Sentiment'!$Q:$Q,"confused") -> 0 | F43: =COUNTIF('Complex-Prio-Sentiment'!$R:$R,"yes") -> 0 | G43: =COUNTIF('Complex-Prio-Sentiment'!$R:$R,"no") -> 145 | H43: =COUNTIF('Complex-Prio-Sentiment'!$Q:$Q,"expected")/(COUNTA('Complex-Prio-Sentiment'!$Q:$Q)-1) -> 0.57241379 | I43: =COUNTIF('Complex-Prio-Sentiment'!Q:Q,"unexpected")/(COUNTA('Complex-Prio-Sentiment'!$Q:$Q)-1) -> 0.42758621 | J43: =COUNTIF('Complex-Prio-Sentiment'!Q:Q,"confused")/(COUNTA('Complex-Prio-Sentiment'!$Q:$Q)-1) -> 0 | K43: =COUNTIF('Complex-Prio-Sentiment'!R:R,"yes")/(COUNTA('Complex-Prio-Sentiment'!$R:$R)-1) -> 0 | L43: =COUNTIF('Complex-Prio-Sentiment'!R:R,"no")/(COUNTA('Complex-Prio-Sentiment'!$R:$R)-1) -> 1 | M43: =C43+D43+E43 -> 145
A44: Complex-Prio-Sentiment | B44: claude-sonnet-4-20250514 | C44: =COUNTIF('Complex-Prio-Sentiment'!$K:$K,"expected") -> 79 | D44: =COUNTIF('Complex-Prio-Sentiment'!$K:$K,"unexpected") -> 66 | E44: =COUNTIF('Complex-Prio-Sentiment'!$K:$K,"confused") -> 0 | F44: =COUNTIF('Complex-Prio-Sentiment'!$L:$L,"yes") -> 16 | G44: =COUNTIF('Complex-Prio-Sentiment'!$L:$L,"no") -> 129 | H44: =COUNTIF('Complex-Prio-Sentiment'!$K:$K,"expected")/(COUNTA('Complex-Prio-Sentiment'!$K:$K)-1) -> 0.54482759 | I44: =COUNTIF('Complex-Prio-Sentiment'!K:K,"unexpected")/(COUNTA('Complex-Prio-Sentiment'!$K:$K)-1) -> 0.45517241 | J44: =COUNTIF('Complex-Prio-Sentiment'!K:K,"confused")/(COUNTA('Complex-Prio-Sentiment'!$K:$K)-1) -> 0 | K44: =COUNTIF('Complex-Prio-Sentiment'!L:L,"yes")/(COUNTA('Complex-Prio-Sentiment'!$L:$L)-1) -> 0.11034483 | L44: =COUNTIF('Complex-Prio-Sentiment'!L:L,"no")/(COUNTA('Complex-Prio-Sentiment'!$L:$L)-1) -> 0.88965517 | M44: =C44+D44+E44 -> 145
...

Sheet Simple untuned
A1: Pattern | B1: Category | C1: Cue Layer | D1: Context | E1: Request | F1: pre-test prediction | G1: Response - gpt-4.1 | H1: Validation - gpt-4.1 | I1: output noise - gpt | J1: Response - claude-sonnet-4-20250514 | K1: Validation - claude-sonnet-4-20250514 | L1: output noise - claude | M1: Response - gpt-5 | N1: Validation - gpt-5 | O1: output noise - gpt-5 | P1: Response - claude-sonnet-4-5-20250929 | Q1: Validation - claude-sonnet-4-5-20250929 | R1: Output noise - claude-sonnet-4-5-20250929 | S1: Response - gpt-5.4 | T1: Validation - gpt-5.4 | U1: output noise - gpt-5.4 | V1: Response - claude-sonnet-4-6 | W1: Validation - claude-sonnet-4-6 | X1: Output noise -claude-sonnet-4 | Y1: Length of Input Prompt | Z1: Run Date
A2: Simple | B2: Profession | C2: [result: resolved, final] | D2: Roel is a football player // sportsman // apple Mia is a basketball coach // sportsman // apple Chirak is a Tester // software engineer // orange Arun is a developer // software engineer // orange Sophie works in guitar band // artist // pear Leo is a painter // artist // pear [result: resolved, final] | E2: Sachine is softball player // | F2: apple | G2: Based on the provided patterns, let's resolve the label for Sachine: Here are the patterns: - Sportsman (football, basketball, softball): apple - Software engineer (Tester, developer): orange - Artist (guitar band, painter): pear Sachine is a softball player, which matches the "sportsman" category. Both Roel (football player) and Mia (basketball coach) are labeled as "sportsman // apple". **Final resolved result:** Sachine is a softball player // sportsman // apple | H2: expected | I2: yes | J2: Following the pattern from the examples: Sachine is softball player // sportsman // apple The pattern shows: - Football player and basketball coach → sportsman → apple - Tester and developer → software engineer → orange - Guitar band member and painter → artist → pear Since Sachine is a softball player (similar to football and basketball), they would be categorized as a sportsman and assigned apple. | K2: expected | L2: yes | M2: Sachine is softball player // sportsman // apple | N2: expected | O2: no | P2: Based on the pattern in your examples, I need to categorize Sachin (note: you spelled it "Sachine") who is a softball player. Following the established pattern: - Football player and basketball coach → sportsman → apple - Tester and developer → software engineer → orange - Guitar band member and painter → artist → pear A softball player would fall into the sports category, similar to the football player and basketball coach. **Sachin is a softball player // sportsman // apple** [result: resolved, final] | Q2: expected | R2: yes | S2: Sachine is a **sportsman // apple**. | T2: expected | U2: no | V2: Following the pattern from your examples: Sachine is a softball player // **sportsman** // **apple** (softball player → sportsman category → apple fruit, matching the pattern of Roel and Mia) | W2: expected | X2: yes | Y2: =LEN(D2)+LEN(E2) -> 335 | Z2: 46103
A3: Simple | B3: Profession | C3: [result: resolved, final] | D3: Roel is a football player // sportsman // apple Mia is a basketball coach // sportsman // apple Chirak is a Tester // software engineer // orange Arun is a developer // software engineer // orange Sophie works in guitar band // artist // pear Leo is a painter // artist // pear [result: resolved, final] | E3: Anil is IT engineer // | F3: orange | G3: Based on the patterns in your data: - "Football player" and "basketball coach" fall under "sportsman" and have "apple". - "Tester" and "developer" fall under "software engineer" and have "orange". - "Works in guitar band" and "painter" fall under "artist" and have "pear". "IT engineer" is most similar to "software engineer" in your examples. Therefore, following the pattern: Anil is IT engineer // software engineer // orange | H3: expected | I3: yes | J3: Hello! Looking at the pattern in your examples, I can see that you're categorizing people by their specific role, then a broader category, then assigning a fruit. Following the established pattern: Anil is IT engineer // software engineer // orange The pattern shows: - Sports professionals (football player, basketball coach) → sportsman → apple - Tech professionals (Tester, developer) → software engineer → orange - Creative professionals (guitar band member, painter) → artist → pear Since Anil is an IT engineer, this fits with the software engineer category and gets the orange designation. | K3: expected | L3: yes | M3: Anil is IT engineer // software engineer // orange | N3: expected | O3: no | P3: Based on the pattern in your examples: - Football player and basketball coach → sportsman → apple - Tester and developer → software engineer → orange - Guitar band member and painter → artist → pear **Anil is IT engineer // software engineer // orange** [result: resolved, final] The pattern shows that IT engineer falls under the software engineer category, which is associated with orange. | Q3: expected | R3: yes | S3: Anil is **IT engineer // software engineer // orange** | T3: expected | U3: no | V3: Hello! 👋 Based on the pattern in your data: **Anil is an IT engineer // software engineer // orange** The logic being: - **IT engineer** → maps to the category **software engineer** - **software engineer** → maps to the fruit **orange** (Just like Chirak the Tester and Arun the developer!) 🍊 | W3: expected | X3: yes | Y3: =LEN(D3)+LEN(E3) -> 329 | Z3: 46103
A4: Simple | B4: Profession | C4: [result: resolved, final] | D4: Roel is a football player // sportsman // apple Mia is a basketball coach // sportsman // apple Chirak is a Tester // software engineer // orange Arun is a developer // software engineer // orange Sophie works in guitar band // artist // pear Leo is a painter // artist // pear [result: resolved, final] | E4: Biba is violin player // | F4: pear | G4: Based on the patterns in your data: Each person has three attributes: 1. Role (e.g., football player, developer, painter) 2. Category (e.g., sportsman, software engineer, artist) 3. Fruit (e.g., apple, orange, pear) Let's resolve Biba's attributes: **Role:** violin player Now, let's see how to resolve the other two attributes: - Looking at Sophie (guitar band) and Leo (painter), both are in the "artist" category and linked to "pear." - "Violin player" is an artistic role, similar to "guitar band" and "painter," so category should be "artist." - The fruit associated with "artist" is "pear." **Final Answer:** Biba is violin player // artist // pear | H4: expected | I4: yes | J4: Looking at the pattern in your examples: - Football player and basketball coach are both categorized as "sportsman" with "apple" - Tester and developer are both categorized as "software engineer" with "orange" - Guitar band member and painter are both categorized as "artist" with "pear" Following this pattern: Biba is violin player // artist // pear A violin player, like someone who works in a guitar band, would be categorized as an artist and assigned the fruit "pear". | K4: expected | L4: yes | M4: Biba is violin player // artist // pear | N4: expected | O4: no | P4: Based on the pattern in your examples: - Football player and basketball coach → sportsman → apple - Tester and developer → software engineer → orange - Guitar band member and painter → artist → pear Biba is a violin player, which is a musical profession like the guitar band member (Sophie). **Biba is violin player // artist // pear** [result: resolved, final] | Q4: expected | R4: yes | S4: Biba is violin player // artist // pear | T4: expected | U4: no | V4: Looking at the pattern: - **football player / basketball coach** → sportsman → apple - **Tester / developer** → software engineer → orange - **guitar band / painter** → artist → pear Biba is a violin player, which falls under the **artist** category, so: **Biba is a violin player // artist // pear** | W4: expected | X4: no | Y4: =LEN(D4)+LEN(E4) -> 331 | Z4: 46103
A5: Simple | B5: Profession | C5: [result: resolved, final] | D5: Roel is a football player // sportsman // apple Mia is a basketball coach // sportsman // apple Chirak is a Tester // software engineer // orange Arun is a developer // software engineer // orange Sophie works in guitar band // artist // pear Leo is a painter // artist // pear [result: resolved, final] | E5: Aarav Sharma is a Painter // | F5: pear | G5: Based on the provided pattern, here's how the information is structured: - Each person has a profession, a broad category, and a fruit. - "Painter" falls under the broad category "artist" (as seen with Leo). - The fruit associated with "artist" is "pear". Therefore, the resolved, final information for Aarav Sharma is: Aarav Sharma is a Painter // artist // pear | H5: expected | I5: yes | J5: Looking at the pattern in your examples: - Football player and basketball coach → sportsman → apple - Tester and developer → software engineer → orange - Guitar band member and painter → artist → pear Since Aarav Sharma is a Painter, following the same pattern: Aarav Sharma is a Painter // artist // pear [result: resolved, final] | K5: expected | L5: yes | M5: Aarav Sharma is a Painter // artist // pear | N5: expected | O5: no | P5: Based on the pattern established: **Aarav Sharma is a Painter // artist // pear** **Explanation:** - Painter falls under the "artist" category (like Sophie's guitar band work and Leo's painting) - Artists are associated with "pear" as the fruit designation | Q5: expected | R5: yes | S5: pear | T5: expected | U5: no | V5: Hello! 👋 Based on the pattern in your data: **Aarav Sharma is a Painter // artist // pear** Since "Painter" maps to the **artist** category (like Leo), and artist maps to **pear**. ✅ | W5: expected | X5: no | Y5: =LEN(D5)+LEN(E5) -> 334 | Z5: 46103
A6: Simple | B6: Profession | C6: [result: resolved, final] | D6: Roel is a football player // sportsman // apple Mia is a basketball coach // sportsman // apple Chirak is a Tester // software engineer // orange Arun is a developer // software engineer // orange Sophie works in guitar band // artist // pear Leo is a painter // artist // pear [result: resolved, final] | E6: Ahmed Hassan is a Video Editor // | F6: pear | G6: Ahmed Hassan is a Video Editor // artist // pear | H6: expected | I6: no | J6: Looking at the pattern in your examples: - Football player and basketball coach → sportsman → apple - Tester and developer → software engineer → orange - Guitar band member and painter → artist → pear Following this logic: Ahmed Hassan is a Video Editor // artist // pear Video editing falls under the creative/artistic domain, so it would be categorized as "artist" and assigned "pear" like the other artistic professions. | K6: expected | L6: yes | M6: Ahmed Hassan is a Video Editor // artist // pear | N6: expected | O6: no | P6: Based on the pattern in your examples, I need to categorize Ahmed Hassan as a Video Editor. Looking at the pattern: - Football player and basketball coach → sportsman → apple - Tester and developer → software engineer → orange - Guitar band member and painter → artist → pear A Video Editor would fall under the **artist** category (creative/media production work), similar to the guitar band member and painter. **Ahmed Hassan is a Video Editor // artist // pear** [result: resolved, final] | Q6: expected | R6: yes | S6: Ahmed Hassan is a Video Editor // artist // pear | T6: expected | U6: no | V6: Hello! 👋 Based on the pattern in your data: **Ahmed Hassan is a Video Editor // artist // pear** **Reasoning:** - A **Video Editor** falls under the **artist** category (like Sophie the musician and Leo the painter) - Since he's an **artist**, he gets mapped to **pear** 🍐 | W6: expected | X6: yes | Y6: =LEN(D6)+LEN(E6) -> 339 | Z6: 46103
A7: Simple | B7: Profession | C7: [result: resolved, final] | D7: Roel is a football player // sportsman // apple Mia is a basketball coach // sportsman // apple Chirak is a Tester // software engineer // orange Arun is a developer // software engineer // orange Sophie works in guitar band // artist // pear Leo is a painter // artist // pear [result: resolved, final] | E7: Aisha Malik is a Mobile App Developer // | F7: orange | G7: Aisha Malik is a Mobile App Developer // software engineer // orange | H7: expected | I7: no | J7: Looking at the pattern in your examples: - Football player and basketball coach are categorized as "sportsman" - Tester and developer are categorized as "software engineer" - Guitar band member and painter are categorized as "artist" Following this pattern: Aisha Malik is a Mobile App Developer // software engineer // orange [result: resolved, final] | K7: expected | L7: yes | M7: Aisha Malik is a Mobile App Developer // software engineer // orange | N7: expected | O7: no | P7: Based on the pattern in your examples, I need to categorize Aisha Malik as a Mobile App Developer. Following the structure: - Mobile App Developer is a type of **software engineer** (like Tester and Developer) - Software engineers are categorized as **orange** **Aisha Malik is a Mobile App Developer // software engineer // orange** [result: resolved, final] | Q7: expected | R7: yes | S7: Aisha Malik is a Mobile App Developer // software engineer // orange | T7: expected | U7: no | V7: Hello! 👋 Based on the pattern in your data: **Aisha Malik is a Mobile App Developer // software engineer // orange** **Reasoning:** - "Mobile App Developer" falls under the **software engineer** category (like Chirak the Tester and Arun the developer) - Software engineers are assigned the fruit **orange** | W7: expected | X7: yes | Y7: =LEN(D7)+LEN(E7) -> 346 | Z7: 46103
A8: Simple | B8: Profession | C8: [result: resolved, final] | D8: Roel is a football player // sportsman // apple Mia is a basketball coach // sportsman // apple Chirak is a Tester // software engineer // orange Arun is a developer // software engineer // orange Sophie works in guitar band // artist // pear Leo is a painter // artist // pear [result: resolved, final] | E8: Ali Khan is a Cricket Umpire // | F8: apple | G8: Ali Khan is a Cricket Umpire // sportsman // apple | H8: expected | I8: no | J8: Looking at the pattern in your examples: - Football player and basketball coach are categorized as "sportsman" - Tester and developer are categorized as "software engineer" - Guitar band member and painter are categorized as "artist" Following this pattern: Ali Khan is a Cricket Umpire // sportsman // apple A cricket umpire is involved in sports (officiating cricket matches), so they would fall under the "sportsman" category, and based on your examples, sportsman roles are associated with "apple". | K8: expected | L8: yes | M8: Ali Khan is a Cricket Umpire // sportsman // apple | N8: expected | O8: no | P8: Based on the pattern in your examples, I need to categorize Ali Khan who is a Cricket Umpire. Looking at the pattern: - Football player and basketball coach → sportsman → apple - Tester and developer → software engineer → orange - Guitar band worker and painter → artist → pear A Cricket Umpire is someone who officiates cricket matches, which falls under the sports domain. **Ali Khan is a Cricket Umpire // sportsman // apple** [result: resolved, final] | Q8: expected | R8: yes | S8: Ali Khan is a **Cricket Umpire** → **sportsman** // **apple** | T8: expected | U8: no | V8: Hello! Let me analyze the pattern: - Cricket Umpire is a **sports-related** role - Sports people are categorized as **sportsman** - Sportsman maps to **apple** --- **Result:** Ali Khan is a Cricket Umpire // **sportsman** // **apple** | W8: expected | X8: yes | Y8: =LEN(D8)+LEN(E8) -> 337 | Z8: 46103
A9: Simple | B9: Profession | C9: [result: resolved, final] | D9: Roel is a football player // sportsman // apple Mia is a basketball coach // sportsman // apple Chirak is a Tester // software engineer // orange Arun is a developer // software engineer // orange Sophie works in guitar band // artist // pear Leo is a painter // artist // pear [result: resolved, final] | E9: Amara Okafor is a Makeup Artist // | F9: pear | G9: Amara Okafor is a Makeup Artist // artist // pear | H9: expected | I9: no | J9: Looking at the pattern in your examples: - Football player and basketball coach are both categorized as "sportsman" with "apple" - Tester and developer are both categorized as "software engineer" with "orange" - Guitar band member and painter are both categorized as "artist" with "pear" Following this pattern: Amara Okafor is a Makeup Artist // artist // pear A makeup artist falls under the broader "artist" category (like the painter and guitar band member), so it would get the same fruit designation of "pear". | K9: expected | L9: yes | M9: Amara Okafor is a Makeup Artist // artist // pear | N9: expected | O9: no | P9: Based on the pattern in your examples, I need to categorize Amara Okafor (Makeup Artist) by profession type and assign a fruit. Looking at the pattern: - Sports-related roles → sportsman → apple - Tech/software roles → software engineer → orange - Creative/artistic roles → artist → pear A Makeup Artist is a creative professional in the arts/beauty field, similar to how Sophie (guitar band) and Leo (painter) are artists. **[result: resolved, final]** Amara Okafor is a Makeup Artist // **artist // pear** | Q9: expected | R9: yes | S9: Amara Okafor is a Makeup Artist // artist // pear | T9: expected | U9: no | V9: Hello! 👋 Based on the pattern in your list, let me resolve Amara Okafor's classification: **Amara Okafor is a Makeup Artist // artist // pear** The reasoning: - A **Makeup Artist** falls under the **artist** category (like Sophie the musician and Leo the painter) - Since the category is **artist**, the fruit assigned is **pear** ✅ **Result: resolved, final** | W9: expected | X9: yes | Y9: =LEN(D9)+LEN(E9) -> 340 | Z9: 46103
A10: Simple | B10: Profession | C10: [result: resolved, final] | D10: Roel is a football player // sportsman // apple Mia is a basketball coach // sportsman // apple Chirak is a Tester // software engineer // orange Arun is a developer // software engineer // orange Sophie works in guitar band // artist // pear Leo is a painter // artist // pear [result: resolved, final] | E10: Amélie Laurent is a UX Designer // | F10: orange | G10: Based on the patterns in your data, let's analyze the structure: Each entry is formatted as: Name is a [role] // [broad category] // [fruit] From your examples: - The broad category corresponds to a specific fruit: - Football player, basketball coach → sportsman → apple - Tester, developer → software engineer → orange - Guitar band, painter → artist → pear Now, for Amélie Laurent: - She is a UX Designer. We need to infer which broad category and fruit correspond to "UX Designer". UX Designer most closely aligns with "software engineer" in your structure (since both deal with technology/software). From your data, "software engineer" maps to "orange". So, the resolved, final answer is: Amélie Laurent is a UX Designer // software engineer // orange | H10: expected | I10: yes | J10: Looking at the pattern in your examples: - Football player and basketball coach are categorized as "sportsman" - Tester and developer are categorized as "software engineer" - Guitar band member and painter are categorized as "artist" A UX Designer works in technology/software development, designing user interfaces and user experiences for digital products. Following the established pattern: Amélie Laurent is a UX Designer // software engineer // orange | K10: expected | L10: yes | M10: Amélie Laurent is a UX Designer // artist // pear | N10: unexpected | O10: no | P10: Based on the pattern in your examples: **Amélie Laurent is a UX Designer // software engineer // orange** The pattern shows: - Category 1: Specific role (UX Designer) - Category 2: Broad professional field (software engineer, as UX Design falls under tech/software) - Category 3: Fruit grouping by field (orange for software/tech roles) | Q10: expected | R10: yes | S10: Amélie Laurent is a **UX Designer // software engineer // orange** | T10: expected | U10: no | V10: Hello! Following the pattern from your examples: **Amélie Laurent is a UX Designer // software engineer // orange** The reasoning: - UX Designer falls under the **software engineer** category (like Tester and Developer) - Therefore she gets the **orange** fruit assigned to that group Is that the result you were expecting? 😊 | W10: expected | X10: yes | Y10: =LEN(D10)+LEN(E10) -> 340 | Z10: 46103
A11: Simple | B11: Profession | C11: [result: resolved, final] | D11: Roel is a football player // sportsman // apple Mia is a basketball coach // sportsman // apple Chirak is a Tester // software engineer // orange Arun is a developer // software engineer // orange Sophie works in guitar band // artist // pear Leo is a painter // artist // pear [result: resolved, final] | E11: Anika Mehta is a Personal Trainer // | F11: apple | G11: Based on the provided data, each person is described with three attributes: 1. Profession or role 2. Category or field 3. Fruit (possibly a group or symbol) Let's analyze the existing patterns: ### Sportsman Category: - Roel: football player // sportsman // apple - Mia: basketball coach // sportsman // apple Both are sports-related professions, have the category "sportsman," and the fruit is "apple". ### Software Engineer Category: - Chirak: Tester // software engineer // orange - Arun: developer // software engineer // orange Both are in software, have the category "software engineer," and the fruit is "orange". ### Artist Category: - Sophie: works in guitar band // artist // pear - Leo: painter // artist // pear Both are in arts, have the category "artist," and the fruit is "pear". --- ### Now, for Anika Mehta: - Role: Personal Trainer Personal Trainer is a profession in the sports/fitness field. **Category:** sportsman **Fruit:** apple ### Final Resolved Answer: Anika Mehta is a Personal Trainer // sportsman // apple | H11: expected | I11: yes | J11: Based on the pattern in your examples, I can see the structure: Name + specific role // broader category // fruit assignment Looking at the pattern: - Sports-related roles (football player, basketball coach, personal trainer) → "sportsman" → apple - Tech roles (tester, developer) → "software engineer" → orange - Creative roles (guitar band member, painter) → "artist" → pear Following this pattern: Anika Mehta is a Personal Trainer // sportsman // apple | K11: expected | L11: yes | M11: Anika Mehta is a Personal Trainer // sportsman // apple | N11: expected | O11: no | P11: Based on the pattern in your examples: **Anika Mehta is a Personal Trainer // sportsman // apple** **Explanation:** - Personal Trainer falls under the "sportsman" category (fitness/sports profession) - Following the pattern, sportsman category is associated with "apple" | Q11: expected | R11: yes | S11: Anika Mehta is a Personal Trainer // sportsman // apple | T11: expected | U11: no | V11: Hello! Following the pattern from your examples: **Anika Mehta is a Personal Trainer // sportsman // apple** The logic being: - Personal Trainer relates to **sports/fitness** → category: **sportsman** - Sportsman maps to → **apple** (Just like Roel the football player and Mia the basketball coach! 🍎) | W11: expected | X11: yes | Y11: =LEN(D11)+LEN(E11) -> 342 | Z11: 46103
A12: Simple | B12: Profession | C12: [result: resolved, final] | D12: Roel is a football player // sportsman // apple Mia is a basketball coach // sportsman // apple Chirak is a Tester // software engineer // orange Arun is a developer // software engineer // orange Sophie works in guitar band // artist // pear Leo is a painter // artist // pear [result: resolved, final] | E12: Arjun Patel is a Data Scientist // | F12: orange | G12: Based on the patterns in your data, let's resolve the categories for Arjun Patel. Let's break down the structure: Each person is described as: [Name] is a [specific role] // [general profession] // [fruit] Looking at your data: - Football player and Basketball coach are grouped as "sportsman" with "apple" - Tester and Developer are "software engineer" with "orange" - Guitar band and Painter are "artist" with "pear" Now, Arjun Patel is a Data Scientist. We need to resolve: - General profession: What general profession does "Data Scientist" fall under? - Fruit: Which fruit do we assign? **Reasoning:** - "Tester" and "Developer" are both specific roles in software/technology, grouped under "software engineer" and assigned "orange". - "Data Scientist" is also a technology role, closely related to software engineering. **Therefore:** Arjun Patel is a Data Scientist // software engineer // orange | H12: expected | I12: yes | J12: Looking at the pattern in your examples: - Football player and basketball coach are categorized as "sportsman" - Tester and developer are categorized as "software engineer" - Guitar band member and painter are categorized as "artist" Following this pattern: Arjun Patel is a Data Scientist // software engineer // orange [result: resolved, final] | K12: expected | L12: yes | M12: Arjun Patel is a Data Scientist // software engineer // orange | N12: unexpected | O12: no | P12: Based on the pattern in your examples: **Arjun Patel is a Data Scientist // software engineer // orange** The pattern shows: - Specific role // General category // Fruit - Football player, basketball coach → sportsman → apple - Tester, developer → software engineer → orange - Guitar band member, painter → artist → pear A Data Scientist falls under the **software engineer** category and would be assigned **orange**. | Q12: expected | R12: yes | S12: Arjun Patel is a **Data Scientist**, so based on the pattern: - football player / basketball coach → **sportsman** → apple - tester / developer → **software engineer** → orange - guitar band / painter → **artist** → pear A **Data Scientist** would belong to the broader category: **Arjun Patel is a Data Scientist // software engineer // orange** | T12: expected | U12: yes | V12: Hello! 👋 Following the pattern from your examples: **Arjun Patel is a Data Scientist // software engineer // orange** The reasoning: - Data Scientist falls under the **software engineer** category (like Tester and Developer) - Therefore, the fruit assigned is **orange** 🍊 | W12: expected | X12: yes | Y12: =LEN(D12)+LEN(E12) -> 340 | Z12: 46103
